[2023-04-29T01:02:25.994+0000] {taskinstance.py:1090} INFO - Dependencies all met for dep_context=non-requeueable deps ti=<TaskInstance: booking_ingestion_DAG.load_data manual__2023-04-29T01:02:21.371636+00:00 [queued]>
[2023-04-29T01:02:26.005+0000] {taskinstance.py:1090} INFO - Dependencies all met for dep_context=requeueable deps ti=<TaskInstance: booking_ingestion_DAG.load_data manual__2023-04-29T01:02:21.371636+00:00 [queued]>
[2023-04-29T01:02:26.006+0000] {taskinstance.py:1288} INFO - 
--------------------------------------------------------------------------------
[2023-04-29T01:02:26.007+0000] {taskinstance.py:1289} INFO - Starting attempt 1 of 1
[2023-04-29T01:02:26.008+0000] {taskinstance.py:1290} INFO - 
--------------------------------------------------------------------------------
[2023-04-29T01:02:26.026+0000] {taskinstance.py:1309} INFO - Executing <Task(PythonOperator): load_data> on 2023-04-29 01:02:21.371636+00:00
[2023-04-29T01:02:26.030+0000] {standard_task_runner.py:55} INFO - Started process 1900 to run task
[2023-04-29T01:02:26.033+0000] {standard_task_runner.py:82} INFO - Running: ['***', 'tasks', 'run', 'booking_ingestion_DAG', 'load_data', 'manual__2023-04-29T01:02:21.371636+00:00', '--job-id', '87', '--raw', '--subdir', 'DAGS_FOLDER/main.py', '--cfg-path', '/tmp/tmpnc8tdlgu']
[2023-04-29T01:02:26.035+0000] {standard_task_runner.py:83} INFO - Job 87: Subtask load_data
[2023-04-29T01:02:26.110+0000] {task_command.py:389} INFO - Running <TaskInstance: booking_ingestion_DAG.load_data manual__2023-04-29T01:02:21.371636+00:00 [running]> on host 0e14e6a5e88f
[2023-04-29T01:02:26.331+0000] {taskinstance.py:1518} INFO - Exporting the following env vars:
AIRFLOW_CTX_DAG_OWNER=***
AIRFLOW_CTX_DAG_ID=booking_ingestion_DAG
AIRFLOW_CTX_TASK_ID=load_data
AIRFLOW_CTX_EXECUTION_DATE=2023-04-29T01:02:21.371636+00:00
AIRFLOW_CTX_TRY_NUMBER=1
AIRFLOW_CTX_DAG_RUN_ID=manual__2023-04-29T01:02:21.371636+00:00
[2023-04-29T01:02:26.372+0000] {taskinstance.py:1776} ERROR - Task failed with exception
Traceback (most recent call last):
  File "/home/airflow/.local/lib/python3.7/site-packages/airflow/operators/python.py", line 175, in execute
    return_value = self.execute_callable()
  File "/home/airflow/.local/lib/python3.7/site-packages/airflow/operators/python.py", line 192, in execute_callable
    return self.python_callable(*self.op_args, **self.op_kwargs)
  File "/opt/airflow/dags/main.py", line 84, in load_data
    data.to_csv(f"{dag_path}/processed_data/processed_data.csv", index=False)
  File "/home/airflow/.local/lib/python3.7/site-packages/pandas/core/generic.py", line 3482, in to_csv
    storage_options=storage_options,
  File "/home/airflow/.local/lib/python3.7/site-packages/pandas/io/formats/format.py", line 1105, in to_csv
    csv_formatter.save()
  File "/home/airflow/.local/lib/python3.7/site-packages/pandas/io/formats/csvs.py", line 243, in save
    storage_options=self.storage_options,
  File "/home/airflow/.local/lib/python3.7/site-packages/pandas/io/common.py", line 707, in get_handle
    newline="",
PermissionError: [Errno 13] Permission denied: '/opt/airflow/processed_data/processed_data.csv'
[2023-04-29T01:02:26.396+0000] {taskinstance.py:1332} INFO - Marking task as FAILED. dag_id=booking_ingestion_DAG, task_id=load_data, execution_date=20230429T010221, start_date=20230429T010225, end_date=20230429T010226
[2023-04-29T01:02:26.426+0000] {standard_task_runner.py:105} ERROR - Failed to execute job 87 for task load_data ([Errno 13] Permission denied: '/opt/airflow/processed_data/processed_data.csv'; 1900)
[2023-04-29T01:02:26.448+0000] {local_task_job.py:212} INFO - Task exited with return code 1
[2023-04-29T01:02:26.478+0000] {taskinstance.py:2596} INFO - 0 downstream tasks scheduled from follow-on schedule check
